2018-11-29 16:18:22,303 ERROR: Exception on /favicon.ico [GET] [in /home/kush/Envs/flask/lib/python3.6/site-packages/flask/app.py:1761]
Traceback (most recent call last):
  File "/home/kush/Envs/flask/lib/python3.6/site-packages/flask/app.py", line 1813, in full_dispatch_request
    rv = self.dispatch_request()
  File "/home/kush/Envs/flask/lib/python3.6/site-packages/flask/app.py", line 1791, in dispatch_request
    self.raise_routing_exception(req)
  File "/home/kush/Envs/flask/lib/python3.6/site-packages/flask/app.py", line 1774, in raise_routing_exception
    raise request.routing_exception
  File "/home/kush/Envs/flask/lib/python3.6/site-packages/flask/ctx.py", line 336, in match_request
    self.url_adapter.match(return_rule=True)
  File "/home/kush/Envs/flask/lib/python3.6/site-packages/werkzeug/routing.py", line 1581, in match
    raise NotFound()
werkzeug.exceptions.NotFound: 404 Not Found: The requested URL was not found on the server.  If you entered the URL manually please check your spelling and try again.

During handling of the above exception, another exception occurred:

Traceback (most recent call last):
  File "/home/kush/Envs/flask/lib/python3.6/site-packages/flask/app.py", line 2292, in wsgi_app
    response = self.full_dispatch_request()
  File "/home/kush/Envs/flask/lib/python3.6/site-packages/flask/app.py", line 1815, in full_dispatch_request
    rv = self.handle_user_exception(e)
  File "/home/kush/Envs/flask/lib/python3.6/site-packages/flask/app.py", line 1713, in handle_user_exception
    return self.handle_http_exception(e)
  File "/home/kush/Envs/flask/lib/python3.6/site-packages/flask/app.py", line 1644, in handle_http_exception
    return handler(e)
  File "/home/kush/repos/microblog/app/errors.py", line 6, in not_found_error
    return render_tempalte('404.html'), 404
NameError: name 'render_tempalte' is not defined
2018-11-29 16:18:23,326 ERROR: Exception on /favicon.ico [GET] [in /home/kush/Envs/flask/lib/python3.6/site-packages/flask/app.py:1761]
Traceback (most recent call last):
  File "/home/kush/Envs/flask/lib/python3.6/site-packages/flask/app.py", line 1813, in full_dispatch_request
    rv = self.dispatch_request()
  File "/home/kush/Envs/flask/lib/python3.6/site-packages/flask/app.py", line 1791, in dispatch_request
    self.raise_routing_exception(req)
  File "/home/kush/Envs/flask/lib/python3.6/site-packages/flask/app.py", line 1774, in raise_routing_exception
    raise request.routing_exception
  File "/home/kush/Envs/flask/lib/python3.6/site-packages/flask/ctx.py", line 336, in match_request
    self.url_adapter.match(return_rule=True)
  File "/home/kush/Envs/flask/lib/python3.6/site-packages/werkzeug/routing.py", line 1581, in match
    raise NotFound()
werkzeug.exceptions.NotFound: 404 Not Found: The requested URL was not found on the server.  If you entered the URL manually please check your spelling and try again.

During handling of the above exception, another exception occurred:

Traceback (most recent call last):
  File "/home/kush/Envs/flask/lib/python3.6/site-packages/flask/app.py", line 2292, in wsgi_app
    response = self.full_dispatch_request()
  File "/home/kush/Envs/flask/lib/python3.6/site-packages/flask/app.py", line 1815, in full_dispatch_request
    rv = self.handle_user_exception(e)
  File "/home/kush/Envs/flask/lib/python3.6/site-packages/flask/app.py", line 1713, in handle_user_exception
    return self.handle_http_exception(e)
  File "/home/kush/Envs/flask/lib/python3.6/site-packages/flask/app.py", line 1644, in handle_http_exception
    return handler(e)
  File "/home/kush/repos/microblog/app/errors.py", line 6, in not_found_error
    return render_tempalte('404.html'), 404
NameError: name 'render_tempalte' is not defined
2018-11-29 16:18:24,873 ERROR: Exception on /favicon.ico [GET] [in /home/kush/Envs/flask/lib/python3.6/site-packages/flask/app.py:1761]
Traceback (most recent call last):
  File "/home/kush/Envs/flask/lib/python3.6/site-packages/flask/app.py", line 1813, in full_dispatch_request
    rv = self.dispatch_request()
  File "/home/kush/Envs/flask/lib/python3.6/site-packages/flask/app.py", line 1791, in dispatch_request
    self.raise_routing_exception(req)
  File "/home/kush/Envs/flask/lib/python3.6/site-packages/flask/app.py", line 1774, in raise_routing_exception
    raise request.routing_exception
  File "/home/kush/Envs/flask/lib/python3.6/site-packages/flask/ctx.py", line 336, in match_request
    self.url_adapter.match(return_rule=True)
  File "/home/kush/Envs/flask/lib/python3.6/site-packages/werkzeug/routing.py", line 1581, in match
    raise NotFound()
werkzeug.exceptions.NotFound: 404 Not Found: The requested URL was not found on the server.  If you entered the URL manually please check your spelling and try again.

During handling of the above exception, another exception occurred:

Traceback (most recent call last):
  File "/home/kush/Envs/flask/lib/python3.6/site-packages/flask/app.py", line 2292, in wsgi_app
    response = self.full_dispatch_request()
  File "/home/kush/Envs/flask/lib/python3.6/site-packages/flask/app.py", line 1815, in full_dispatch_request
    rv = self.handle_user_exception(e)
  File "/home/kush/Envs/flask/lib/python3.6/site-packages/flask/app.py", line 1713, in handle_user_exception
    return self.handle_http_exception(e)
  File "/home/kush/Envs/flask/lib/python3.6/site-packages/flask/app.py", line 1644, in handle_http_exception
    return handler(e)
  File "/home/kush/repos/microblog/app/errors.py", line 6, in not_found_error
    return render_tempalte('404.html'), 404
NameError: name 'render_tempalte' is not defined
2018-11-29 16:18:33,209 ERROR: Exception on /favicon.ico [GET] [in /home/kush/Envs/flask/lib/python3.6/site-packages/flask/app.py:1761]
Traceback (most recent call last):
  File "/home/kush/Envs/flask/lib/python3.6/site-packages/flask/app.py", line 1813, in full_dispatch_request
    rv = self.dispatch_request()
  File "/home/kush/Envs/flask/lib/python3.6/site-packages/flask/app.py", line 1791, in dispatch_request
    self.raise_routing_exception(req)
  File "/home/kush/Envs/flask/lib/python3.6/site-packages/flask/app.py", line 1774, in raise_routing_exception
    raise request.routing_exception
  File "/home/kush/Envs/flask/lib/python3.6/site-packages/flask/ctx.py", line 336, in match_request
    self.url_adapter.match(return_rule=True)
  File "/home/kush/Envs/flask/lib/python3.6/site-packages/werkzeug/routing.py", line 1581, in match
    raise NotFound()
werkzeug.exceptions.NotFound: 404 Not Found: The requested URL was not found on the server.  If you entered the URL manually please check your spelling and try again.

During handling of the above exception, another exception occurred:

Traceback (most recent call last):
  File "/home/kush/Envs/flask/lib/python3.6/site-packages/flask/app.py", line 2292, in wsgi_app
    response = self.full_dispatch_request()
  File "/home/kush/Envs/flask/lib/python3.6/site-packages/flask/app.py", line 1815, in full_dispatch_request
    rv = self.handle_user_exception(e)
  File "/home/kush/Envs/flask/lib/python3.6/site-packages/flask/app.py", line 1713, in handle_user_exception
    return self.handle_http_exception(e)
  File "/home/kush/Envs/flask/lib/python3.6/site-packages/flask/app.py", line 1644, in handle_http_exception
    return handler(e)
  File "/home/kush/repos/microblog/app/errors.py", line 6, in not_found_error
    return render_tempalte('404.html'), 404
NameError: name 'render_tempalte' is not defined
2018-11-29 16:19:02,228 ERROR: Exception on /favicon.ico [GET] [in /home/kush/Envs/flask/lib/python3.6/site-packages/flask/app.py:1761]
Traceback (most recent call last):
  File "/home/kush/Envs/flask/lib/python3.6/site-packages/flask/app.py", line 1813, in full_dispatch_request
    rv = self.dispatch_request()
  File "/home/kush/Envs/flask/lib/python3.6/site-packages/flask/app.py", line 1791, in dispatch_request
    self.raise_routing_exception(req)
  File "/home/kush/Envs/flask/lib/python3.6/site-packages/flask/app.py", line 1774, in raise_routing_exception
    raise request.routing_exception
  File "/home/kush/Envs/flask/lib/python3.6/site-packages/flask/ctx.py", line 336, in match_request
    self.url_adapter.match(return_rule=True)
  File "/home/kush/Envs/flask/lib/python3.6/site-packages/werkzeug/routing.py", line 1581, in match
    raise NotFound()
werkzeug.exceptions.NotFound: 404 Not Found: The requested URL was not found on the server.  If you entered the URL manually please check your spelling and try again.

During handling of the above exception, another exception occurred:

Traceback (most recent call last):
  File "/home/kush/Envs/flask/lib/python3.6/site-packages/flask/app.py", line 2292, in wsgi_app
    response = self.full_dispatch_request()
  File "/home/kush/Envs/flask/lib/python3.6/site-packages/flask/app.py", line 1815, in full_dispatch_request
    rv = self.handle_user_exception(e)
  File "/home/kush/Envs/flask/lib/python3.6/site-packages/flask/app.py", line 1713, in handle_user_exception
    return self.handle_http_exception(e)
  File "/home/kush/Envs/flask/lib/python3.6/site-packages/flask/app.py", line 1644, in handle_http_exception
    return handler(e)
  File "/home/kush/repos/microblog/app/errors.py", line 6, in not_found_error
    return render_tempalte('404.html'), 404
NameError: name 'render_tempalte' is not defined
